<?xml version="1.0"?>
<robot xmlns:xacro="http://www.ros.org/wiki/xacro"  name="robot">

    <!-- This is an example of a URDF. -->
    <!-- As we move through the file, new things to note will be pointed out. -->
    <!-- It's not meant an example of GOOD design, but an example of some of the various features of URDF/xacro. -->

    <!-- Package Name -->
    <xacro:property name="package" value="ros2_control_demo_3r_robot" />

    <!-- This will include all the contents of example_include.xacro first. Go check it out! -->
    <xacro:include filename="example_include.xacro" />
    <xacro:include filename="create_link.xacro" />

    <!-- Variables -->
    <xacro:property name="pi" value="3.1415926535897931" />

    <!-- This first link called "world" is empty -->
    <link name="world" />

    <!-- A simple fixed joint from our empty world link, to our base. -->
    <!-- The base origin is offset from the world origin. -->
    <joint name="base_joint" type="fixed">
        <origin xyz="0 0 0" rpy="0 0 0"/>
        <parent link="world"/>
        <child link="link_0"/>        
    </joint>

    <xacro:addlink name="link_0">
        <xacro:addvis>
            <origin xyz="0 0 0" rpy="0 0 0"/>
            <xacro:addmesh mesh_file="link_0.stl"/>
            <xacro:addcolor color="idk" rgba="1.0 0.0 0.0 1.0"/>
        </xacro:addvis>
        <xacro:addcollide mu="0" kp="1000.0" kd="1.0">
            <origin xyz="0 0 0" rpy="0 0 0"/>
            <xacro:addmesh mesh_file="link_0.stl"/>
        </xacro:addcollide>
        <xacro:addinertia mass="100">
            <origin xyz="0 0 0" rpy="0 0 0"/>
            <inertia ixx="0.1" ixy="0.0" ixz="0.0" iyy="0.1" iyz="0.0" izz="0.1"/>
        </xacro:addinertia> 
    </xacro:addlink>

    <joint name="joint_0" type="fixed">
        <parent link="link_0"/>
        <child link="link_1"/>
        <origin rpy="0 0 0" xyz="0 0 0"/>
        <axis xyz="0 0 1"/>
        <limit lower="-3.14" upper="3.14" effort="1000" velocity="0.5"/>
    </joint>

    <xacro:addlink name="link_1">
        <xacro:addvis>
            <origin xyz="0 0 0" rpy="0 0 0"/>
            <xacro:addmesh mesh_file="link_1.stl"/>
            <xacro:addcolor color="green" rgba="0.2 1 0.2 1.0"/>
        </xacro:addvis>
        <xacro:addcollide mu="0" kp="1000.0" kd="1.0">
            <origin xyz="0 0 0" rpy="0 0 0"/>
            <xacro:addmesh mesh_file="link_1.stl"/>
        </xacro:addcollide>
        <xacro:addinertia mass="25">
            <origin xyz="0 0 0" rpy="0 0 0"/>
            <inertia ixx="0.001" ixy="0.0" ixz="0.0" iyy="0.001" iyz="0.0" izz="0.001" />
        </xacro:addinertia> 
    </xacro:addlink>

    <joint name="joint_1" type="revolute">
        <parent link="link_0"/>
        <child link="link_1"/>
        <origin rpy="0 0 0" xyz="0 0 0.1"/>
        <axis xyz="0 0 1"/>
        <limit lower="-3.14" upper="3.14" effort="1000" velocity="0.5"/>
        <dynamics damping="0" friction="0"/>
    </joint>

    <xacro:addlink name="link_2">
        <xacro:addvis>
            <origin xyz="0 0 0" rpy="0 0 0"/>
            <xacro:addmesh mesh_file="link_2.stl"/>
            <xacro:addcolor color="green" rgba="0.2 1 0.2 1.0"/>
        </xacro:addvis>
        <xacro:addcollide mu="0" kp="1000.0" kd="1.0">
            <origin xyz="0 0 0" rpy="0 0 0"/>
            <xacro:addmesh mesh_file="link_2.stl"/>
        </xacro:addcollide>
        <xacro:addinertia mass="15">
            <origin xyz="0 0 0" rpy="0 0 0"/>
            <inertia ixx="0.001" ixy="0.0" ixz="0.0" iyy="0.001" iyz="0.0" izz="0.001" />
        </xacro:addinertia> 
    </xacro:addlink>

    <joint name="joint_2" type="revolute">
        <parent link="link_1"/>
        <child link="link_2"/>
        <origin rpy="${pi/2} 0 0" xyz="0 0 0"/>
        <axis xyz="0 0 1"/>
        <limit lower="-3.14" upper="3.14" effort="0.5" velocity="0.5"/>
        <dynamics damping="10" friction="10"/>
    </joint>

    <xacro:addlink name="link_3">
        <xacro:addvis>
            <origin xyz="0 0 0" rpy="0 0 0"/>
            <xacro:addmesh mesh_file="link_3.stl"/>
            <xacro:addcolor color="green" rgba="0.2 1 0.2 1.0"/>
        </xacro:addvis>
        <xacro:addcollide mu="0" kp="1000.0" kd="1.0">
            <origin xyz="0 0 0" rpy="0 0 0"/>
            <xacro:addmesh mesh_file="link_3.stl"/>
        </xacro:addcollide>
        <xacro:addinertia mass="5">
            <origin xyz="0 0 0" rpy="0 0 0"/>
            <inertia ixx="0.001" ixy="0.0" ixz="0.0" iyy="0.001" iyz="0.0" izz="0.001" />
        </xacro:addinertia> 
    </xacro:addlink>

    <joint name="joint_3" type="revolute">
        <parent link="link_2"/>
        <child link="link_3"/>
        <origin rpy="0 0 0" xyz="0.15 0 0"/>
        <axis xyz="0 0 1"/>
        <limit lower="-3.14" upper="3.14" effort="1000" velocity="0.5"/>
        <dynamics damping="10" friction="10"/>
    </joint>

    <joint name="joint_eff" type="fixed">
        <parent link="link_3"/>
        <child link="end_effector"/>
        <origin rpy="1.57 0 1.57" xyz="0.26 0 0"/>
        <axis xyz="0 0 1"/>
    </joint>
    
    <link name="end_effector" />

    <xacro:include filename="example_gazebo.xacro" />

</robot>